Workbook

Sheet График
A1: ПО ДОГОВОРУ | K1: РЕСТРАКТЫ | V1: УСЛОВИЯ РЕСТРАКТА
A2: Дата с учетом нерабочих дней | B2: № | C2: Срок начало | D2: Срок конец | E2: Кол-во дней | F2: Возврат основной суммы долга | G2: Возврат начисленных % | H2: Ежемесячный платеж по кредиту | I2: остаток ссудной задолженности после платежа | K2: Дата с учетом нерабочих дней | L2: № | M2: Срок начало | N2: Срок конец | O2: Кол-во дней | P2: Возврат основной суммы долга | Q2: Возврат начисленных % | R2: Ежемесячный платеж по кредиту | S2: остаток задолженности на начало периода | T2: Комиссия за рестракт | V2: Key | W2: Номер рестракта | X2: Характеристика | Y2: Значение
A3: =(IF((WEEKDAY(D3,16)<3)+(COUNTIF(Нерабочие[],D3)>0),WORKDAY(D3,1,Нерабочие[]),D3)) -> 44159 | B3: 0 | C3: 44144 | D3: 44159 | E3: 15 | G3: 1223.3607 | I3: 150000 | K3: =(IF((WEEKDAY(N3,16)<3)+(COUNTIF(Нерабочие[],N3)>0),WORKDAY(N3,1,Нерабочие[]),N3)) -> 2 | V3: =УслРестрактов[[#This Row],[Номер рестракта]]&УслРестрактов[[#This Row],[Характеристика]] -> 1Дата реструктуризации | W3: 1 | X3: Дата реструктуризации
A4: =(IF((WEEKDAY(D4,16)<3)+(COUNTIF(Нерабочие[],D4)>0),WORKDAY(D4,1,Нерабочие[]),D4)) -> 44174 | B4: 1 | C4: 44144 | D4: 44174 | E4: 30 | F4: 0 | G4: 1223.36 | H4: 1223.36 | I4: 150000 | K4: =(IF((WEEKDAY(N4,16)<3)+(COUNTIF(Нерабочие[],N4)>0),WORKDAY(N4,1,Нерабочие[]),N4)) -> 2 | V4: =УслРестрактов[[#This Row],[Номер рестракта]]&УслРестрактов[[#This Row],[Характеристика]] -> 1Дата погашения новая | W4: 1 | X4: Дата погашения новая
A5: =(IF((WEEKDAY(D5,16)<3)+(COUNTIF(Нерабочие[],D5)>0),WORKDAY(D5,1,Нерабочие[]),D5)) -> 44207 | B5: 2 | C5: 44174 | D5: 44205 | E5: 31 | F5: 366.71 | G5: 2530.29 | H5: 2897 | I5: 149633.29 | K5: =(IF((WEEKDAY(N5,16)<3)+(COUNTIF(Нерабочие[],N5)>0),WORKDAY(N5,1,Нерабочие[]),N5)) -> 2 | V5: =УслРестрактов[[#This Row],[Номер рестракта]]&УслРестрактов[[#This Row],[Характеристика]] -> 1Процентная ставка новая 1 | W5: 1 | X5: ="Процентная ставка новая "&УслРестрактов[[#This Row],[Номер рестракта]] -> Процентная ставка новая 1
A6: =(IF((WEEKDAY(D6,16)<3)+(COUNTIF(Нерабочие[],D6)>0),WORKDAY(D6,1,Нерабочие[]),D6)) -> 44236 | B6: 3 | C6: 44205 | D6: 44236 | E6: 31 | F6: 367.99 | G6: 2529.01 | H6: 2897 | I6: 149265.3 | K6: =(IF((WEEKDAY(N6,16)<3)+(COUNTIF(Нерабочие[],N6)>0),WORKDAY(N6,1,Нерабочие[]),N6)) -> 2 | V6: =УслРестрактов[[#This Row],[Номер рестракта]]&УслРестрактов[[#This Row],[Характеристика]] -> 1Тип графика | W6: 1 | X6: Тип графика
A7: =(IF((WEEKDAY(D7,16)<3)+(COUNTIF(Нерабочие[],D7)>0),WORKDAY(D7,1,Нерабочие[]),D7)) -> 44264 | B7: 4 | C7: 44236 | D7: 44264 | E7: 28 | F7: 618.35 | G7: 2278.65 | H7: 2897 | I7: 148646.95 | K7: =(IF((WEEKDAY(N7,16)<3)+(COUNTIF(Нерабочие[],N7)>0),WORKDAY(N7,1,Нерабочие[]),N7)) -> 2 | V7: =УслРестрактов[[#This Row],[Номер рестракта]]&УслРестрактов[[#This Row],[Характеристика]] -> 1Вид реструктуризаций | W7: 1 | X7: Вид реструктуризаций
A8: =(IF((WEEKDAY(D8,16)<3)+(COUNTIF(Нерабочие[],D8)>0),WORKDAY(D8,1,Нерабочие[]),D8)) -> 44295 | B8: 5 | C8: 44264 | D8: 44295 | E8: 31 | F8: 384.66 | G8: 2512.34 | H8: 2897 | I8: 148262.29 | K8: =(IF((WEEKDAY(N8,16)<3)+(COUNTIF(Нерабочие[],N8)>0),WORKDAY(N8,1,Нерабочие[]),N8)) -> 2 | V8: =УслРестрактов[[#This Row],[Номер рестракта]]&УслРестрактов[[#This Row],[Характеристика]] -> 1Код реструктуризации | W8: 1 | X8: Код реструктуризации
A9: =(IF((WEEKDAY(D9,16)<3)+(COUNTIF(Нерабочие[],D9)>0),WORKDAY(D9,1,Нерабочие[]),D9)) -> 44326 | B9: 6 | C9: 44295 | D9: 44325 | E9: 30 | F9: 472 | G9: 2425 | H9: 2897 | I9: 147790.29 | K9: =(IF((WEEKDAY(N9,16)<3)+(COUNTIF(Нерабочие[],N9)>0),WORKDAY(N9,1,Нерабочие[]),N9)) -> 2 | V9: =УслРестрактов[[#This Row],[Номер рестракта]]&УслРестрактов[[#This Row],[Характеристика]] -> 2Дата реструктуризации | W9: 2 | X9: Дата реструктуризации
A10: =(IF((WEEKDAY(D10,16)<3)+(COUNTIF(Нерабочие[],D10)>0),WORKDAY(D10,1,Нерабочие[]),D10)) -> 44356 | B10: 7 | C10: 44325 | D10: 44356 | E10: 31 | F10: 399.14 | G10: 2497.86 | H10: 2897 | I10: 147391.15 | K10: =(IF((WEEKDAY(N10,16)<3)+(COUNTIF(Нерабочие[],N10)>0),WORKDAY(N10,1,Нерабочие[]),N10)) -> 2 | V10: =УслРестрактов[[#This Row],[Номер рестракта]]&УслРестрактов[[#This Row],[Характеристика]] -> 2Дата погашения новая | W10: 2 | X10: Дата погашения новая
A11: =(IF((WEEKDAY(D11,16)<3)+(COUNTIF(Нерабочие[],D11)>0),WORKDAY(D11,1,Нерабочие[]),D11)) -> 44386 | B11: 8 | C11: 44356 | D11: 44386 | E11: 30 | F11: 486.25 | G11: 2410.75 | H11: 2897 | I11: 146904.9 | K11: =(IF((WEEKDAY(N11,16)<3)+(COUNTIF(Нерабочие[],N11)>0),WORKDAY(N11,1,Нерабочие[]),N11)) -> 2 | V11: =УслРестрактов[[#This Row],[Номер рестракта]]&УслРестрактов[[#This Row],[Характеристика]] -> 2Процентная ставка новая 2 | W11: 2 | X11: ="Процентная ставка новая "&УслРестрактов[[#This Row],[Номер рестракта]] -> Процентная ставка новая 2
A12: =(IF((WEEKDAY(D12,16)<3)+(COUNTIF(Нерабочие[],D12)>0),WORKDAY(D12,1,Нерабочие[]),D12)) -> 44417 | B12: 9 | C12: 44386 | D12: 44417 | E12: 31 | F12: 414.11 | G12: 2482.89 | H12: 2897 | I12: 146490.79 | K12: =(IF((WEEKDAY(N12,16)<3)+(COUNTIF(Нерабочие[],N12)>0),WORKDAY(N12,1,Нерабочие[]),N12)) -> 2 | V12: =УслРестрактов[[#This Row],[Номер рестракта]]&УслРестрактов[[#This Row],[Характеристика]] -> 2Тип графика | W12: 2 | X12: Тип графика
A13: =(IF((WEEKDAY(D13,16)<3)+(COUNTIF(Нерабочие[],D13)>0),WORKDAY(D13,1,Нерабочие[]),D13)) -> 44448 | B13: 10 | C13: 44417 | D13: 44448 | E13: 31 | F13: 421.1 | G13: 2475.9 | H13: 2897 | I13: 146069.69 | K13: =(IF((WEEKDAY(N13,16)<3)+(COUNTIF(Нерабочие[],N13)>0),WORKDAY(N13,1,Нерабочие[]),N13)) -> 2 | V13: =УслРестрактов[[#This Row],[Номер рестракта]]&УслРестрактов[[#This Row],[Характеристика]] -> 2Вид реструктуризаций | W13: 2 | X13: Вид реструктуризаций
A14: =(IF((WEEKDAY(D14,16)<3)+(COUNTIF(Нерабочие[],D14)>0),WORKDAY(D14,1,Нерабочие[]),D14)) -> 44480 | B14: 11 | C14: 44448 | D14: 44478 | E14: 30 | F14: 507.86 | G14: 2389.14 | H14: 2897 | I14: 145561.83 | K14: =(IF((WEEKDAY(N14,16)<3)+(COUNTIF(Нерабочие[],N14)>0),WORKDAY(N14,1,Нерабочие[]),N14)) -> 2 | V14: =УслРестрактов[[#This Row],[Номер рестракта]]&УслРестрактов[[#This Row],[Характеристика]] -> 2Код реструктуризации | W14: 2 | X14: Код реструктуризации | Y14: =IFERROR(VLOOKUP(График!Y13,Рестракты[],2,0),0) -> 0
A15: =(IF((WEEKDAY(D15,16)<3)+(COUNTIF(Нерабочие[],D15)>0),WORKDAY(D15,1,Нерабочие[]),D15)) -> 44509 | B15: 12 | C15: 44478 | D15: 44509 | E15: 31 | F15: 436.81 | G15: 2460.19 | H15: 2897 | I15: 145125.02 | K15: =(IF((WEEKDAY(N15,16)<3)+(COUNTIF(Нерабочие[],N15)>0),WORKDAY(N15,1,Нерабочие[]),N15)) -> 2
A16: =(IF((WEEKDAY(D16,16)<3)+(COUNTIF(Нерабочие[],D16)>0),WORKDAY(D16,1,Нерабочие[]),D16)) -> 44539 | B16: 13 | C16: 44509 | D16: 44539 | E16: 30 | F16: 523.31 | G16: 2373.69 | H16: 2897 | I16: 144601.71 | K16: =(IF((WEEKDAY(N16,16)<3)+(COUNTIF(Нерабочие[],N16)>0),WORKDAY(N16,1,Нерабочие[]),N16)) -> 2
A17: =(IF((WEEKDAY(D17,16)<3)+(COUNTIF(Нерабочие[],D17)>0),WORKDAY(D17,1,Нерабочие[]),D17)) -> 44571 | B17: 14 | C17: 44539 | D17: 44570 | E17: 31 | F17: 453.03 | G17: 2443.97 | H17: 2897 | I17: 144148.68 | K17: =(IF((WEEKDAY(N17,16)<3)+(COUNTIF(Нерабочие[],N17)>0),WORKDAY(N17,1,Нерабочие[]),N17)) -> 2
A18: =(IF((WEEKDAY(D18,16)<3)+(COUNTIF(Нерабочие[],D18)>0),WORKDAY(D18,1,Нерабочие[]),D18)) -> 44601 | B18: 15 | C18: 44570 | D18: 44601 | E18: 31 | F18: 460.69 | G18: 2436.31 | H18: 2897 | I18: 143687.99 | K18: =(IF((WEEKDAY(N18,16)<3)+(COUNTIF(Нерабочие[],N18)>0),WORKDAY(N18,1,Нерабочие[]),N18)) -> 2
A19: =(IF((WEEKDAY(D19,16)<3)+(COUNTIF(Нерабочие[],D19)>0),WORKDAY(D19,1,Нерабочие[]),D19)) -> 44629 | B19: 16 | C19: 44601 | D19: 44629 | E19: 28 | F19: 703.49 | G19: 2193.51 | H19: 2897 | I19: 142984.5 | K19: =(IF((WEEKDAY(N19,16)<3)+(COUNTIF(Нерабочие[],N19)>0),WORKDAY(N19,1,Нерабочие[]),N19)) -> 2
A20: =(IF((WEEKDAY(D20,16)<3)+(COUNTIF(Нерабочие[],D20)>0),WORKDAY(D20,1,Нерабочие[]),D20)) -> 44662 | B20: 17 | C20: 44629 | D20: 44660 | E20: 31 | F20: 480.37 | G20: 2416.63 | H20: 2897 | I20: 142504.13 | K20: =(IF((WEEKDAY(N20,16)<3)+(COUNTIF(Нерабочие[],N20)>0),WORKDAY(N20,1,Нерабочие[]),N20)) -> 2
A21: =(IF((WEEKDAY(D21,16)<3)+(COUNTIF(Нерабочие[],D21)>0),WORKDAY(D21,1,Нерабочие[]),D21)) -> 44690 | B21: 18 | C21: 44660 | D21: 44690 | E21: 30 | F21: 566.18 | G21: 2330.82 | H21: 2897 | I21: 141937.95 | K21: =(IF((WEEKDAY(N21,16)<3)+(COUNTIF(Нерабочие[],N21)>0),WORKDAY(N21,1,Нерабочие[]),N21)) -> 2
A22: =(IF((WEEKDAY(D22,16)<3)+(COUNTIF(Нерабочие[],D22)>0),WORKDAY(D22,1,Нерабочие[]),D22)) -> 44721 | B22: 19 | C22: 44690 | D22: 44721 | E22: 31 | F22: 498.05 | G22: 2398.95 | H22: 2897 | I22: 141439.9 | K22: =(IF((WEEKDAY(N22,16)<3)+(COUNTIF(Нерабочие[],N22)>0),WORKDAY(N22,1,Нерабочие[]),N22)) -> 2
A23: =(IF((WEEKDAY(D23,16)<3)+(COUNTIF(Нерабочие[],D23)>0),WORKDAY(D23,1,Нерабочие[]),D23)) -> 44753 | B23: 20 | C23: 44721 | D23: 44751 | E23: 30 | F23: 583.59 | G23: 2313.41 | H23: 2897 | I23: 140856.31 | K23: =(IF((WEEKDAY(N23,16)<3)+(COUNTIF(Нерабочие[],N23)>0),WORKDAY(N23,1,Нерабочие[]),N23)) -> 2
A24: =(IF((WEEKDAY(D24,16)<3)+(COUNTIF(Нерабочие[],D24)>0),WORKDAY(D24,1,Нерабочие[]),D24)) -> 44782 | B24: 21 | C24: 44751 | D24: 44782 | E24: 31 | F24: 516.34 | G24: 2380.66 | H24: 2897 | I24: 140339.97 | K24: =(IF((WEEKDAY(N24,16)<3)+(COUNTIF(Нерабочие[],N24)>0),WORKDAY(N24,1,Нерабочие[]),N24)) -> 2
A25: =(IF((WEEKDAY(D25,16)<3)+(COUNTIF(Нерабочие[],D25)>0),WORKDAY(D25,1,Нерабочие[]),D25)) -> 44813 | B25: 22 | C25: 44782 | D25: 44813 | E25: 31 | F25: 525.06 | G25: 2371.94 | H25: 2897 | I25: 139814.91 | K25: =(IF((WEEKDAY(N25,16)<3)+(COUNTIF(Нерабочие[],N25)>0),WORKDAY(N25,1,Нерабочие[]),N25)) -> 2
A26: =(IF((WEEKDAY(D26,16)<3)+(COUNTIF(Нерабочие[],D26)>0),WORKDAY(D26,1,Нерабочие[]),D26)) -> 44844 | B26: 23 | C26: 44813 | D26: 44843 | E26: 30 | F26: 610.16 | G26: 2286.84 | H26: 2897 | I26: 139204.75 | K26: =(IF((WEEKDAY(N26,16)<3)+(COUNTIF(Нерабочие[],N26)>0),WORKDAY(N26,1,Нерабочие[]),N26)) -> 2
... A117: =(IF((WEEKDAY(D117,16)<3)+(COUNTIF(Нерабочие[],D117)>0),WORKDAY(D117,1,Нерабочие[]),D117)) -> 47612 | B117: 114 | C117: 47582 | D117: 47612 | E117: 30 | F117: 2590.01 | G117: 306.99 | H117: 2897 | I117: 16179.29 | K117: =(IF((WEEKDAY(N117,16)<3)+(COUNTIF(Нерабочие[],N117)>0),WORKDAY(N117,1,Нерабочие[]),N117)) -> 2
A118: =(IF((WEEKDAY(D118,16)<3)+(COUNTIF(Нерабочие[],D118)>0),WORKDAY(D118,1,Нерабочие[]),D118)) -> 47644 | B118: 115 | C118: 47612 | D118: 47643 | E118: 31 | F118: 2623.55 | G118: 273.45 | H118: 2897 | I118: 13555.74
A119: =(IF((WEEKDAY(D119,16)<3)+(COUNTIF(Нерабочие[],D119)>0),WORKDAY(D119,1,Нерабочие[]),D119)) -> 47673 | B119: 116 | C119: 47643 | D119: 47673 | E119: 30 | F119: 2675.28 | G119: 221.72 | H119: 2897 | I119: 10880.46 | K119: Дата с учетом нерабочих дней | L119: № | M119: Срок начало | N119: Срок конец | O119: Кол-во дней | P119: Возврат основной суммы долга | Q119: Возврат начисленных % | R119: Ежемесячный платеж по кредиту | S119: остаток задолженности на начало периода | T119: Комиссия за рестракт
A120: =(IF((WEEKDAY(D120,16)<3)+(COUNTIF(Нерабочие[],D120)>0),WORKDAY(D120,1,Нерабочие[]),D120)) -> 47704 | B120: 117 | C120: 47673 | D120: 47704 | E120: 31 | F120: 2713.11 | G120: 183.89 | H120: 2897 | I120: 8167.35 | K120: =(IF((WEEKDAY(N120,16)<3)+(COUNTIF(Нерабочие[],N120)>0),WORKDAY(N120,1,Нерабочие[]),N120)) -> 2
A121: =(IF((WEEKDAY(D121,16)<3)+(COUNTIF(Нерабочие[],D121)>0),WORKDAY(D121,1,Нерабочие[]),D121)) -> 47735 | B121: 118 | C121: 47704 | D121: 47735 | E121: 31 | F121: 2758.96 | G121: 138.04 | H121: 2897 | I121: 5408.39 | K121: =(IF((WEEKDAY(N121,16)<3)+(COUNTIF(Нерабочие[],N121)>0),WORKDAY(N121,1,Нерабочие[]),N121)) -> 2
A122: =(IF((WEEKDAY(D122,16)<3)+(COUNTIF(Нерабочие[],D122)>0),WORKDAY(D122,1,Нерабочие[]),D122)) -> 47765 | B122: 119 | C122: 47735 | D122: 47765 | E122: 30 | F122: 2808.54 | G122: 88.46 | H122: 2897 | I122: 2599.85 | K122: =(IF((WEEKDAY(N122,16)<3)+(COUNTIF(Нерабочие[],N122)>0),WORKDAY(N122,1,Нерабочие[]),N122)) -> 2
A123: =(IF((WEEKDAY(D123,16)<3)+(COUNTIF(Нерабочие[],D123)>0),WORKDAY(D123,1,Нерабочие[]),D123)) -> 47798 | B123: 120 | C123: 47765 | D123: 47796 | E123: 31 | F123: 2599.85 | G123: 43.94 | H123: 2643.79 | I123: 0 | K123: =(IF((WEEKDAY(N123,16)<3)+(COUNTIF(Нерабочие[],N123)>0),WORKDAY(N123,1,Нерабочие[]),N123)) -> 2
K124: =(IF((WEEKDAY(N124,16)<3)+(COUNTIF(Нерабочие[],N124)>0),WORKDAY(N124,1,Нерабочие[]),N124)) -> 2
K125: =(IF((WEEKDAY(N125,16)<3)+(COUNTIF(Нерабочие[],N125)>0),WORKDAY(N125,1,Нерабочие[]),N125)) -> 2
K126: =(IF((WEEKDAY(N126,16)<3)+(COUNTIF(Нерабочие[],N126)>0),WORKDAY(N126,1,Нерабочие[]),N126)) -> 2
K127: =(IF((WEEKDAY(N127,16)<3)+(COUNTIF(Нерабочие[],N127)>0),WORKDAY(N127,1,Нерабочие[]),N127)) -> 2
K128: =(IF((WEEKDAY(N128,16)<3)+(COUNTIF(Нерабочие[],N128)>0),WORKDAY(N128,1,Нерабочие[]),N128)) -> 2
K129: =(IF((WEEKDAY(N129,16)<3)+(COUNTIF(Нерабочие[],N129)>0),WORKDAY(N129,1,Нерабочие[]),N129)) -> 2
K130: =(IF((WEEKDAY(N130,16)<3)+(COUNTIF(Нерабочие[],N130)>0),WORKDAY(N130,1,Нерабочие[]),N130)) -> 2
...

Sheet Первоначальный
A1: Номер договора | B1: ZS/2020/021/00
A2: Номер транша
A3: Клиент | B3: 7705810688 | C3: Анна - 51 ООО
A4: Дата выдачи | B4: 44144
A5: Дата погашения по графику | B5: 47796
A6: Сумма | B6: 2000000
A7: Процент неустойки | B7: 0.005
A8: =B4 -> 44144 | B8: 0.199 | C8: Процентная ставка по договору_1
AA9: =IF(COUNTA(AA12:AA1048576)<>0,"ЕСТЬ ДАННЫЕ","") | AB9: =IF(COUNTA(AB12:AB1048576)<>0,"ЕСТЬ ДАННЫЕ","") | AH9: =IF(COUNTA(AH12:AH1048576)<>0,"ЕСТЬ ДАННЫЕ","") | AI9: =IF(COUNTA(AI12:AI1048576)<>0,"ЕСТЬ ДАННЫЕ","") | AJ9: =IF(COUNTA(AJ12:AJ1048576)<>0,"ЕСТЬ ДАННЫЕ","")
C10: ОСТАТКИ НА НАЧАЛО ПЕРИОДА | I10: НАЧИСЛЕНИЯ И ВЫДАЧИ ЗА ПЕРИОД | M10: ГРАФИК И ПОЛУЧЕННЫЕ ПЛАТЕЖИ | Q10: БЛОК ПРОСРОЧКИ | V10: РАСПРЕДЕЛЕНИЕ ПЛАТЕЖЕЙ | AA10: ВСПОМОГАТЕЛЬНЫЙ БЛОК | AG10: ОСТАТКИ НА КОНЕЦ ПЕРИОДА
A11: Дата платежа | B11: Остаток ОД на начало периода | C11: Остаток процентов на начало периода | D11: Остаток процентов на просроченный ОД на начало периода | E11: Остаток прочих комиссий на начало периода | F11: Неустойка на начало периода | G11: Итого остаток на начало периода | H11: Проценты за период | I11: Проценты на просроченный платеж по ОД за период | J11: Комиссия за период | K11: Неустойка за период | L11: Выдача ОД за период | M11: Платеж ОД по графику | N11: Платеж процентов и комиссий по графику | O11: Полученный платеж | P11: Просроченный платеж по ОД | Q11: Просроченный платеж по процентам | R11: Просроченный платеж | S11: Кол-во дней просрочки | T11: Полученный платёж по процентам | U11: Полученный платёж по процентам на просроченный ОД | V11: Полученный платёж по прочим комиссиям | W11: Полученный платёж по ОД | X11: Полученный платёж по неустойке | Y11: Переплата | Z11: Дата платежа из графика | AA11: Досрочное погашение (да/"") | AB11: Цель досрочного погашения (ОД/"") | AC11: Остаток ОД на конец периода | AD11: Остаток процентов на конец периода | AE11: Остаток процентов на просроченный ОД на конец периода | AF11: Остаток прочих комиссий на конец периода | AG11: Неустойка на конец периода | AH11: Списание неустойки | AI11: Списание процентов | AJ11: Списание процентов на просроченный платеж по ОД | AK11: Итого остаток на конец периода | AL11: Рестракт
O12: 0 | Y12: =Первоначальный[[#This Row],[Полученный платеж]] -> 0 | Z12: =IF(TYPE((VLOOKUP(Первоначальный[[#This Row],[Дата платежа]],График[Срок конец],1,0)))=16,"",1)
A13: =$B$4 -> 44144 | L13: 150000 | M13: =SUMIFS(График[Возврат основной суммы долга],График[Дата с учетом нерабочих дней],$A13) -> 0 | N13: =SUMIFS(График[Возврат начисленных %],График[Дата с учетом нерабочих дней],$A13) -> 0 | O13: 0 | P13: {=MAX(IF(AA12="Да",0,SUM(INDIRECT("M"&(MAX(("Да"=AA$12:AA12)*ROW(AA$12:AA12)+1,ROW($P$12))&":M"&(ROW()))))-SUM(INDIRECT("W"&(MAX(("Да"=AA$12:AA12)*ROW(AA$12:AA12)+1,ROW($P$12))&":W"&(ROW()))))),0)} -> 0 | Q13: =MAX(SUM($N$13:N13)-SUM($T$13:T13),0) -> 0 | R13: =Первоначальный[[#This Row],[Просроченный платеж по ОД]]+Первоначальный[[#This Row],[Просроченный платеж по процентам]] -> 0 | S13: =IF(Первоначальный[[#This Row],[Просроченный платеж]]<1,0,S12+1) -> 0 | T13: {=IF(Первоначальный[[#This Row],[Итого остаток на начало периода]]<1,0, IF( AND(TYPE(VLOOKUP(1,$Z$12:Z13,1,0))=16,Первоначальный[[#This Row],[Досрочное погашение (да/"")]]=""),0, _xlfn.IFS(AND(S12=0,Первоначальный[[#This Row],[Дата платежа из графика]]<>1,Первоначальный[[#This Row],[Платеж процентов и комиссий по графику]]<>0,Первоначальный[[#This Row],[Полученный платеж]]<>0),MIN(LOOKUP(,-1/($Z$12:Z13=1),$C$12:C13)+LOOKUP(,-1/($Z$12:Z13=1),$H$12:H13),Первоначальный[[#This Row],[Полученный платеж]]+Y12), AND(Первоначальный[[#This Row],[Досрочное погашение (да/"")]]="Да",Первоначальный[[#This Row],[Цель досрочного погашения (ОД/"")]]<>"ОД"),MIN(Первоначальный[[#This Row],[Полученный платеж]]+Y12,SUM(Первоначальный[[#This Row],[Остаток процентов на начало периода]],Первоначальный[[#This Row],[Проценты за период]])), AND(S12=0,Первоначальный[[#This Row],[Дата платежа из графика]]=""),0, AND(S12=0,Первоначальный[[#This Row],[Дата платежа из графика]]=1,MAX((0<>S$12:S12)*ROW(S$12:S12),ROW($S$12))>=MAX((1=Z$12:Z12)*ROW(Z$12:Z12),ROW($T$12)),TYPE(VLOOKUP("Да",(INDIRECT("AA"&(MAX((1=Z$12:Z12)*ROW(Z$12:Z12),ROW($T$12))&":AA"&(ROW()-1)))),1,0))=16),MIN(LOOKUP(,-1/($Z$12:Z13=1),$C$12:C13)+LOOKUP(,-1/($Z$12:Z13=1),$H$12:H13),Первоначальный[[#This Row],[Полученный платеж]]+Y12), AND(S12=0,TYPE(VLOOKUP("Да",(INDIRECT("AA"&(MAX((1=Z$12:Z12)*ROW(Z$12:Z12),ROW($T$12))&":AA"&(ROW()-1)))),1,0))<>16),MIN(LOOKUP(,-1/($Z$12:Z13=1),$C$12:C13)+LOOKUP(,-1/($Z$12:Z13=1),$H$12:H13)-IF(AA12="Да",0,SUM(INDIRECT("T"&(MAX(("Да"=AA$12:AA12)*ROW(AA$12:AA12)+1,ROW($T$12))&":T"&(ROW()-1))))),Первоначальный[[#This Row],[Полученный платеж]]+Y12), AND(S12=0,MAX((0<>N$12:N12)*ROW(N$12:N12),ROW($S$12))>=MAX((1=Z$12:Z12)*ROW(Z$12:Z12),ROW($T$12))),MIN(LOOKUP(,-1/($Z$12:Z13=1),$C$12:C13)+LOOKUP(,-1/($Z$12:Z13=1),$H$12:H13)-IF(N12<>0,0,SUM(INDIRECT("T"&(MAX((0<>N$12:N12)*ROW(N$12:N12)+1,ROW($T$12))&":T"&(ROW()-1))))),Первоначальный[[#This Row],[Полученный платеж]]+Y12), AND(S12=0,Первоначальный[[#This Row],[Дата платежа из графика]]=1),MIN(LOOKUP(,-1/($Z$12:Z13=1),$C$12:C13)+LOOKUP(,-1/($Z$12:Z13=1),$H$12:H13)-IF(Z12=1,0,SUM(INDIRECT("T"&(MAX((1=Z$12:Z12)*ROW(Z$12:Z12)+1,ROW($T$12))&":T"&(ROW()-1))))),Первоначальный[[#This Row],[Полученный платеж]]+Y12), AND(Z12>0,Первоначальный[[#This Row],[Дата платежа из графика]]=1),MIN(Первоначальный[[#This Row],[Остаток процентов на начало периода]]+Первоначальный[[#This Row],[Проценты за период]],Первоначальный[[#This Row],[Полученный платеж]]+Y12), AND(S12>0,MAX((0<>S$12:S12)*ROW(S$12:S12),ROW($S$12))>=MAX((1=Z$12:Z12)*ROW(Z$12:Z12),ROW($T$12)),TYPE(VLOOKUP("Да",(INDIRECT("AA"&(MAX((1=Z$12:Z12)*ROW(Z$12:Z12),ROW($T$12))&":AA"&(ROW()-1)))),1,0))=16),MIN(LOOKUP(,-1/($Z$12:Z13=1),$C$12:C13)+LOOKUP(,-1/($Z$12:Z13=1),$H$12:H13)-SUM(INDIRECT("T"&(MAX((1=Z$12:Z12)*ROW(Z$12:Z12),ROW($T$12))&":T"&(ROW()-1)))),Первоначальный[[#This Row],[Полученный платеж]]+Y12), S12>0,MIN(LOOKUP(,-1/($Z$12:Z13=1),$C$12:C13)+LOOKUP(,-1/($Z$12:Z13=1),$H$12:H13)-IF(Z12=1,0,SUM(INDIRECT("T"&(MAX((1=Z$12:Z12)*ROW(Z$12:Z12)+1,ROW($T$12))&":T"&(ROW()-1))))),Первоначальный[[#This Row],[Полученный платеж]]+Y12) ) ) )} -> 0 | U13: =MIN(Первоначальный[[#This Row],[Остаток процентов на просроченный ОД на начало периода]]+Первоначальный[[#This Row],[Проценты на просроченный платеж по ОД за период]],Первоначальный[[#This Row],[Полученный платеж]]+Y12-Первоначальный[[#This Row],[Полученный платёж по процентам]]) -> 0 | V13: =MAX(MIN(SUM(O13,Y12)-SUM(T13:T13),SUM(E13,J13)),0) -> 0 | W13: {=IF(Первоначальный[[#This Row],[Итого остаток на начало периода]]<1,0, _xlfn.IFS( AND(TYPE(VLOOKUP(1,$Z$12:Z13,1,0))=16,Первоначальный[[#This Row],[Досрочное погашение (да/"")]]=""),0, AND(S12=0,Первоначальный[[#This Row],[Дата платежа из графика]]<>1,Первоначальный[[#This Row],[Платеж ОД по графику]]<>0,Первоначальный[[#This Row],[Полученный платеж]]<>0),MIN(Первоначальный[[#This Row],[Полученный платеж]]+Y12-SUM(Первоначальный[[#This Row],[Полученный платёж по процентам]],Первоначальный[[#This Row],[Полученный платёж по процентам на просроченный ОД]],Первоначальный[[#This Row],[Полученный платёж по прочим комиссиям]]),VLOOKUP(LOOKUP(,-1/($Z$12:Z13=1),$A$12:A13),График[[Срок конец]:[Возврат основной суммы долга]],3,0)), AND(S12=0,Первоначальный[[#This Row],[Дата платежа из графика]]="",Первоначальный[[#This Row],[Досрочное погашение (да/"")]]<>"Да"),0, AND(S12=0,Первоначальный[[#This Row],[Досрочное погашение (да/"")]]=""),MIN(Первоначальный[[#This Row],[Полученный платеж]]+Y12-SUM(Первоначальный[[#This Row],[Полученный платёж по процентам]],Первоначальный[[#This Row],[Полученный платёж по процентам на просроченный ОД]],Первоначальный[[#This Row],[Полученный платёж по прочим комиссиям]]),VLOOKUP(LOOKUP(,-1/($Z$12:Z13=1),$A$12:A13),График[[Срок конец]:[Возврат основной суммы долга]],3,0)), Первоначальный[[#This Row],[Досрочное погашение (да/"")]]="Да",MIN(Первоначальный[[#This Row],[Полученный платеж]]+Y12-SUM(Первоначальный[[#This Row],[Полученный платёж по процентам]],Первоначальный[[#This Row],[Полученный платёж по процентам на просроченный ОД]],Первоначальный[[#This Row],[Полученный платёж по прочим комиссиям]]),Первоначальный[[#This Row],[Остаток ОД на начало периода]]), S12>0,MIN(Первоначальный[[#This Row],[Полученный платеж]]+Y12-SUM(Первоначальный[[#This Row],[Полученный платёж по процентам]],Первоначальный[[#This Row],[Полученный платёж по процентам на просроченный ОД]],Первоначальный[[#This Row],[Полученный платёж по прочим комиссиям]]),SUM(INDIRECT("M"&(MAX((1=S$12:S12)*ROW(S$12:S12),ROW($W$12))&":M"&(ROW()))))-SUM(INDIRECT("W"&(MAX((1=S$12:S12)*ROW(S$12:S12),ROW($W$12))&":W"&(ROW()-1))))) ) )} -> 0 | X13: =MAX(MIN(SUM(O13,Y12)-SUM(T13:W13),SUM(F13,K13)),0) -> 0 | Y13: =ROUND(Y12+O13-SUM(T13:X13),2) -> 0 | Z13: =IF(TYPE((VLOOKUP(Первоначальный[[#This Row],[Дата платежа]],График[Срок конец],1,0)))=16,"",1) | AC13: =Первоначальный[[#This Row],[Остаток ОД на начало периода]]-Первоначальный[[#This Row],[Полученный платёж по ОД]]+Первоначальный[[#This Row],[Выдача ОД за период]] -> 150000 | AD13: =Первоначальный[[#This Row],[Остаток процентов на начало периода]]+Первоначальный[[#This Row],[Проценты за период]]-Первоначальный[[#This Row],[Полученный платёж по процентам]] -> 0 | AE13: =Первоначальный[[#This Row],[Остаток процентов на просроченный ОД на начало периода]]+Первоначальный[[#This Row],[Проценты на просроченный платеж по ОД за период]]-Первоначальный[[#This Row],[Полученный платёж по процентам на просроченный ОД]] -> 0 | AF13: =Первоначальный[[#This Row],[Остаток прочих комиссий на начало периода]]+Первоначальный[[#This Row],[Комиссия за период]]-Первоначальный[[#This Row],[Полученный платёж по прочим комиссиям]] -> 0 | AG13: =Первоначальный[[#This Row],[Неустойка на начало периода]]+Первоначальный[[#This Row],[Неустойка за период]]-Первоначальный[[#This Row],[Полученный платёж по неустойке]] -> 0 | AK13: =SUM(AC13:AJ13) -> 150000 | AL13: {=MAX((УслРестрактов[Характеристика]="Дата реструктуризации")*(УслРестрактов[Значение]=Первоначальный!$A13),0)} -> 0
A14: =A13+1 -> 44145 | B14: =AC13 -> 150000 | C14: =AD13+AI13 -> 0 | D14: =AE13+AJ13 -> 0 | E14: =AF13 -> 0 | F14: =AG13+AH13 -> 0 | G14: =AK13 -> 150000 | H14: =ROUND($B14*VLOOKUP($A14,$A$1:$B$10,2,1)/(365+IF(MOD(YEAR($A14),4),0,1)*($A14-$A13)),2)-Первоначальный[[#This Row],[Проценты на просроченный платеж по ОД за период]] -> 81.56 | I14: =ROUND(P13*VLOOKUP($A14,$A$1:$B$10,2,1)/(365+IF(MOD(YEAR($A14),4),0,1)*($A14-$A13)),2) -> 0 | J14: 0 | K14: =IF(S14<>0,R14*$B$7,0) -> 0 | L14: 0 | M14: =SUMIFS(График[Возврат основной суммы долга],График[Дата с учетом нерабочих дней],$A14) -> 0 | N14: =SUMIFS(График[Возврат начисленных %],График[Дата с учетом нерабочих дней],$A14) -> 0 | O14: 0 | P14: {=MAX(IF(AA13="Да",0,SUM(INDIRECT("M"&(MAX(("Да"=AA$12:AA13)*ROW(AA$12:AA13)+1,ROW($P$12))&":M"&(ROW()))))-SUM(INDIRECT("W"&(MAX(("Да"=AA$12:AA13)*ROW(AA$12:AA13)+1,ROW($P$12))&":W"&(ROW()))))),0)} -> 0 | Q14: =MAX(SUM($N$13:N14)-SUM($T$13:T14),0) -> 0 | R14: =Первоначальный[[#This Row],[Просроченный платеж по ОД]]+Первоначальный[[#This Row],[Просроченный платеж по процентам]] -> 0 | S14: =IF(Первоначальный[[#This Row],[Просроченный платеж]]<1,0,S13+1) -> 0 | T14: {=IF(Первоначальный[[#This Row],[Итого остаток на начало периода]]<1,0, IF( AND(TYPE(VLOOKUP(1,$Z$12:Z14,1,0))=16,Первоначальный[[#This Row],[Досрочное погашение (да/"")]]=""),0, _xlfn.IFS(AND(S13=0,Первоначальный[[#This Row],[Дата платежа из графика]]<>1,Первоначальный[[#This Row],[Платеж процентов и комиссий по графику]]<>0,Первоначальный[[#This Row],[Полученный платеж]]<>0),MIN(LOOKUP(,-1/($Z$12:Z14=1),$C$12:C14)+LOOKUP(,-1/($Z$12:Z14=1),$H$12:H14),Первоначальный[[#This Row],[Полученный платеж]]+Y13), AND(Первоначальный[[#This Row],[Досрочное погашение (да/"")]]="Да",Первоначальный[[#This Row],[Цель досрочного погашения (ОД/"")]]<>"ОД"),MIN(Первоначальный[[#This Row],[Полученный платеж]]+Y13,SUM(Первоначальный[[#This Row],[Остаток процентов на начало периода]],Первоначальный[[#This Row],[Проценты за период]])), AND(S13=0,Первоначальный[[#This Row],[Дата платежа из графика]]=""),0, AND(S13=0,Первоначальный[[#This Row],[Дата платежа из графика]]=1,MAX((0<>S$12:S13)*ROW(S$12:S13),ROW($S$12))>=MAX((1=Z$12:Z13)*ROW(Z$12:Z13),ROW($T$12)),TYPE(VLOOKUP("Да",(INDIRECT("AA"&(MAX((1=Z$12:Z13)*ROW(Z$12:Z13),ROW($T$12))&":AA"&(ROW()-1)))),1,0))=16),MIN(LOOKUP(,-1/($Z$12:Z14=1),$C$12:C14)+LOOKUP(,-1/($Z$12:Z14=1),$H$12:H14),Первоначальный[[#This Row],[Полученный платеж]]+Y13), AND(S13=0,TYPE(VLOOKUP("Да",(INDIRECT("AA"&(MAX((1=Z$12:Z13)*ROW(Z$12:Z13),ROW($T$12))&":AA"&(ROW()-1)))),1,0))<>16),MIN(LOOKUP(,-1/($Z$12:Z14=1),$C$12:C14)+LOOKUP(,-1/($Z$12:Z14=1),$H$12:H14)-IF(AA13="Да",0,SUM(INDIRECT("T"&(MAX(("Да"=AA$12:AA13)*ROW(AA$12:AA13)+1,ROW($T$12))&":T"&(ROW()-1))))),Первоначальный[[#This Row],[Полученный платеж]]+Y13), AND(S13=0,MAX((0<>N$12:N13)*ROW(N$12:N13),ROW($S$12))>=MAX((1=Z$12:Z13)*ROW(Z$12:Z13),ROW($T$12))),MIN(LOOKUP(,-1/($Z$12:Z14=1),$C$12:C14)+LOOKUP(,-1/($Z$12:Z14=1),$H$12:H14)-IF(N13<>0,0,SUM(INDIRECT("T"&(MAX((0<>N$12:N13)*ROW(N$12:N13)+1,ROW($T$12))&":T"&(ROW()-1))))),Первоначальный[[#This Row],[Полученный платеж]]+Y13), AND(S13=0,Первоначальный[[#This Row],[Дата платежа из графика]]=1),MIN(LOOKUP(,-1/($Z$12:Z14=1),$C$12:C14)+LOOKUP(,-1/($Z$12:Z14=1),$H$12:H14)-IF(Z13=1,0,SUM(INDIRECT("T"&(MAX((1=Z$12:Z13)*ROW(Z$12:Z13)+1,ROW($T$12))&":T"&(ROW()-1))))),Первоначальный[[#This Row],[Полученный платеж]]+Y13), AND(Z13>0,Первоначальный[[#This Row],[Дата платежа из графика]]=1),MIN(Первоначальный[[#This Row],[Остаток процентов на начало периода]]+Первоначальный[[#This Row],[Проценты за период]],Первоначальный[[#This Row],[Полученный платеж]]+Y13), AND(S13>0,MAX((0<>S$12:S13)*ROW(S$12:S13),ROW($S$12))>=MAX((1=Z$12:Z13)*ROW(Z$12:Z13),ROW($T$12)),TYPE(VLOOKUP("Да",(INDIRECT("AA"&(MAX((1=Z$12:Z13)*ROW(Z$12:Z13),ROW($T$12))&":AA"&(ROW()-1)))),1,0))=16),MIN(LOOKUP(,-1/($Z$12:Z14=1),$C$12:C14)+LOOKUP(,-1/($Z$12:Z14=1),$H$12:H14)-SUM(INDIRECT("T"&(MAX((1=Z$12:Z13)*ROW(Z$12:Z13),ROW($T$12))&":T"&(ROW()-1)))),Первоначальный[[#This Row],[Полученный платеж]]+Y13), S13>0,MIN(LOOKUP(,-1/($Z$12:Z14=1),$C$12:C14)+LOOKUP(,-1/($Z$12:Z14=1),$H$12:H14)-IF(Z13=1,0,SUM(INDIRECT("T"&(MAX((1=Z$12:Z13)*ROW(Z$12:Z13)+1,ROW($T$12))&":T"&(ROW()-1))))),Первоначальный[[#This Row],[Полученный платеж]]+Y13) ) ) )} -> 0 | U14: =MIN(Первоначальный[[#This Row],[Остаток процентов на просроченный ОД на начало периода]]+Первоначальный[[#This Row],[Проценты на просроченный платеж по ОД за период]],Первоначальный[[#This Row],[Полученный платеж]]+Y13-Первоначальный[[#This Row],[Полученный платёж по процентам]]) -> 0 | V14: =MAX(MIN(SUM(O14,Y13)-SUM(T14:T14),SUM(E14,J14)),0) -> 0 | W14: {=IF(Первоначальный[[#This Row],[Итого остаток на начало периода]]<1,0, _xlfn.IFS( AND(TYPE(VLOOKUP(1,$Z$12:Z14,1,0))=16,Первоначальный[[#This Row],[Досрочное погашение (да/"")]]=""),0, AND(S13=0,Первоначальный[[#This Row],[Дата платежа из графика]]<>1,Первоначальный[[#This Row],[Платеж ОД по графику]]<>0,Первоначальный[[#This Row],[Полученный платеж]]<>0),MIN(Первоначальный[[#This Row],[Полученный платеж]]+Y13-SUM(Первоначальный[[#This Row],[Полученный платёж по процентам]],Первоначальный[[#This Row],[Полученный платёж по процентам на просроченный ОД]],Первоначальный[[#This Row],[Полученный платёж по прочим комиссиям]]),VLOOKUP(LOOKUP(,-1/($Z$12:Z14=1),$A$12:A14),График[[Срок конец]:[Возврат основной суммы долга]],3,0)), AND(S13=0,Первоначальный[[#This Row],[Дата платежа из графика]]="",Первоначальный[[#This Row],[Досрочное погашение (да/"")]]<>"Да"),0, AND(S13=0,Первоначальный[[#This Row],[Досрочное погашение (да/"")]]=""),MIN(Первоначальный[[#This Row],[Полученный платеж]]+Y13-SUM(Первоначальный[[#This Row],[Полученный платёж по процентам]],Первоначальный[[#This Row],[Полученный платёж по процентам на просроченный ОД]],Первоначальный[[#This Row],[Полученный платёж по прочим комиссиям]]),VLOOKUP(LOOKUP(,-1/($Z$12:Z14=1),$A$12:A14),График[[Срок конец]:[Возврат основной суммы долга]],3,0)), Первоначальный[[#This Row],[Досрочное погашение (да/"")]]="Да",MIN(Первоначальный[[#This Row],[Полученный платеж]]+Y13-SUM(Первоначальный[[#This Row],[Полученный платёж по процентам]],Первоначальный[[#This Row],[Полученный платёж по процентам на просроченный ОД]],Первоначальный[[#This Row],[Полученный платёж по прочим комиссиям]]),Первоначальный[[#This Row],[Остаток ОД на начало периода]]), S13>0,MIN(Первоначальный[[#This Row],[Полученный платеж]]+Y13-SUM(Первоначальный[[#This Row],[Полученный платёж по процентам]],Первоначальный[[#This Row],[Полученный платёж по процентам на просроченный ОД]],Первоначальный[[#This Row],[Полученный платёж по прочим комиссиям]]),SUM(INDIRECT("M"&(MAX((1=S$12:S13)*ROW(S$12:S13),ROW($W$12))&":M"&(ROW()))))-SUM(INDIRECT("W"&(MAX((1=S$12:S13)*ROW(S$12:S13),ROW($W$12))&":W"&(ROW()-1))))) ) )} -> 0 | X14: =MAX(MIN(SUM(O14,Y13)-SUM(T14:W14),SUM(F14,K14)),0) -> 0 | Y14: =ROUND(Y13+O14-SUM(T14:X14),2) -> 0 | Z14: =IF(TYPE((VLOOKUP(Первоначальный[[#This Row],[Дата платежа]],График[Срок конец],1,0)))=16,"",1) | AC14: =Первоначальный[[#This Row],[Остаток ОД на начало периода]]-Первоначальный[[#This Row],[Полученный платёж по ОД]]+Первоначальный[[#This Row],[Выдача ОД за период]] -> 150000 | AD14: =Первоначальный[[#This Row],[Остаток процентов на начало периода]]+Первоначальный[[#This Row],[Проценты за период]]-Первоначальный[[#This Row],[Полученный платёж по процентам]] -> 81.56 | AE14: =Первоначальный[[#This Row],[Остаток процентов на просроченный ОД на начало периода]]+Первоначальный[[#This Row],[Проценты на просроченный платеж по ОД за период]]-Первоначальный[[#This Row],[Полученный платёж по процентам на просроченный ОД]] -> 0 | AF14: =Первоначальный[[#This Row],[Остаток прочих комиссий на начало периода]]+Первоначальный[[#This Row],[Комиссия за период]]-Первоначальный[[#This Row],[Полученный платёж по прочим комиссиям]] -> 0 | AG14: =Первоначальный[[#This Row],[Неустойка на начало периода]]+Первоначальный[[#This Row],[Неустойка за период]]-Первоначальный[[#This Row],[Полученный платёж по неустойке]] -> 0 | AK14: =SUM(AC14:AJ14) -> 150081.56 | AL14: {=MAX((УслРестрактов[Характеристика]="Дата реструктуризации")*(УслРестрактов[Значение]=Первоначальный!$A14),0)} -> 0
A15: =A14+1 -> 44146 | B15: =AC14 -> 150000 | C15: =AD14+AI14 -> 81.56 | D15: =AE14+AJ14 -> 0 | E15: =AF14 -> 0 | F15: =AG14+AH14 -> 0 | G15: =AK14 -> 150081.56 | H15: =ROUND($B15*VLOOKUP($A15,$A$1:$B$10,2,1)/(365+IF(MOD(YEAR($A15),4),0,1)*($A15-$A14)),2)-Первоначальный[[#This Row],[Проценты на просроченный платеж по ОД за период]] -> 81.56 | I15: =ROUND(P14*VLOOKUP($A15,$A$1:$B$10,2,1)/(365+IF(MOD(YEAR($A15),4),0,1)*($A15-$A14)),2) -> 0 | J15: 0 | K15: =IF(S15<>0,R15*$B$7,0) -> 0 | L15: 0 | M15: =SUMIFS(График[Возврат основной суммы долга],График[Дата с учетом нерабочих дней],$A15) -> 0 | N15: =SUMIFS(График[Возврат начисленных %],График[Дата с учетом нерабочих дней],$A15) -> 0 | O15: 0 | P15: {=MAX(IF(AA14="Да",0,SUM(INDIRECT("M"&(MAX(("Да"=AA$12:AA14)*ROW(AA$12:AA14)+1,ROW($P$12))&":M"&(ROW()))))-SUM(INDIRECT("W"&(MAX(("Да"=AA$12:AA14)*ROW(AA$12:AA14)+1,ROW($P$12))&":W"&(ROW()))))),0)} -> 0 | Q15: =MAX(SUM($N$13:N15)-SUM($T$13:T15),0) -> 0 | R15: =Первоначальный[[#This Row],[Просроченный платеж по ОД]]+Первоначальный[[#This Row],[Просроченный платеж по процентам]] -> 0 | S15: =IF(Первоначальный[[#This Row],[Просроченный платеж]]<1,0,S14+1) -> 0 | T15: {=IF(Первоначальный[[#This Row],[Итого остаток на начало периода]]<1,0, IF( AND(TYPE(VLOOKUP(1,$Z$12:Z15,1,0))=16,Первоначальный[[#This Row],[Досрочное погашение (да/"")]]=""),0, _xlfn.IFS(AND(S14=0,Первоначальный[[#This Row],[Дата платежа из графика]]<>1,Первоначальный[[#This Row],[Платеж процентов и комиссий по графику]]<>0,Первоначальный[[#This Row],[Полученный платеж]]<>0),MIN(LOOKUP(,-1/($Z$12:Z15=1),$C$12:C15)+LOOKUP(,-1/($Z$12:Z15=1),$H$12:H15),Первоначальный[[#This Row],[Полученный платеж]]+Y14), AND(Первоначальный[[#This Row],[Досрочное погашение (да/"")]]="Да",Первоначальный[[#This Row],[Цель досрочного погашения (ОД/"")]]<>"ОД"),MIN(Первоначальный[[#This Row],[Полученный платеж]]+Y14,SUM(Первоначальный[[#This Row],[Остаток процентов на начало периода]],Первоначальный[[#This Row],[Проценты за период]])), AND(S14=0,Первоначальный[[#This Row],[Дата платежа из графика]]=""),0, AND(S14=0,Первоначальный[[#This Row],[Дата платежа из графика]]=1,MAX((0<>S$12:S14)*ROW(S$12:S14),ROW($S$12))>=MAX((1=Z$12:Z14)*ROW(Z$12:Z14),ROW($T$12)),TYPE(VLOOKUP("Да",(INDIRECT("AA"&(MAX((1=Z$12:Z14)*ROW(Z$12:Z14),ROW($T$12))&":AA"&(ROW()-1)))),1,0))=16),MIN(LOOKUP(,-1/($Z$12:Z15=1),$C$12:C15)+LOOKUP(,-1/($Z$12:Z15=1),$H$12:H15),Первоначальный[[#This Row],[Полученный платеж]]+Y14), AND(S14=0,TYPE(VLOOKUP("Да",(INDIRECT("AA"&(MAX((1=Z$12:Z14)*ROW(Z$12:Z14),ROW($T$12))&":AA"&(ROW()-1)))),1,0))<>16),MIN(LOOKUP(,-1/($Z$12:Z15=1),$C$12:C15)+LOOKUP(,-1/($Z$12:Z15=1),$H$12:H15)-IF(AA14="Да",0,SUM(INDIRECT("T"&(MAX(("Да"=AA$12:AA14)*ROW(AA$12:AA14)+1,ROW($T$12))&":T"&(ROW()-1))))),Первоначальный[[#This Row],[Полученный платеж]]+Y14), AND(S14=0,MAX((0<>N$12:N14)*ROW(N$12:N14),ROW($S$12))>=MAX((1=Z$12:Z14)*ROW(Z$12:Z14),ROW($T$12))),MIN(LOOKUP(,-1/($Z$12:Z15=1),$C$12:C15)+LOOKUP(,-1/($Z$12:Z15=1),$H$12:H15)-IF(N14<>0,0,SUM(INDIRECT("T"&(MAX((0<>N$12:N14)*ROW(N$12:N14)+1,ROW($T$12))&":T"&(ROW()-1))))),Первоначальный[[#This Row],[Полученный платеж]]+Y14), AND(S14=0,Первоначальный[[#This Row],[Дата платежа из графика]]=1),MIN(LOOKUP(,-1/($Z$12:Z15=1),$C$12:C15)+LOOKUP(,-1/($Z$12:Z15=1),$H$12:H15)-IF(Z14=1,0,SUM(INDIRECT("T"&(MAX((1=Z$12:Z14)*ROW(Z$12:Z14)+1,ROW($T$12))&":T"&(ROW()-1))))),Первоначальный[[#This Row],[Полученный платеж]]+Y14), AND(Z14>0,Первоначальный[[#This Row],[Дата платежа из графика]]=1),MIN(Первоначальный[[#This Row],[Остаток процентов на начало периода]]+Первоначальный[[#This Row],[Проценты за период]],Первоначальный[[#This Row],[Полученный платеж]]+Y14), AND(S14>0,MAX((0<>S$12:S14)*ROW(S$12:S14),ROW($S$12))>=MAX((1=Z$12:Z14)*ROW(Z$12:Z14),ROW($T$12)),TYPE(VLOOKUP("Да",(INDIRECT("AA"&(MAX((1=Z$12:Z14)*ROW(Z$12:Z14),ROW($T$12))&":AA"&(ROW()-1)))),1,0))=16),MIN(LOOKUP(,-1/($Z$12:Z15=1),$C$12:C15)+LOOKUP(,-1/($Z$12:Z15=1),$H$12:H15)-SUM(INDIRECT("T"&(MAX((1=Z$12:Z14)*ROW(Z$12:Z14),ROW($T$12))&":T"&(ROW()-1)))),Первоначальный[[#This Row],[Полученный платеж]]+Y14), S14>0,MIN(LOOKUP(,-1/($Z$12:Z15=1),$C$12:C15)+LOOKUP(,-1/($Z$12:Z15=1),$H$12:H15)-IF(Z14=1,0,SUM(INDIRECT("T"&(MAX((1=Z$12:Z14)*ROW(Z$12:Z14)+1,ROW($T$12))&":T"&(ROW()-1))))),Первоначальный[[#This Row],[Полученный платеж]]+Y14) ) ) )} -> 0 | U15: =MIN(Первоначальный[[#This Row],[Остаток процентов на просроченный ОД на начало периода]]+Первоначальный[[#This Row],[Проценты на просроченный платеж по ОД за период]],Первоначальный[[#This Row],[Полученный платеж]]+Y14-Первоначальный[[#This Row],[Полученный платёж по процентам]]) -> 0 | V15: =MAX(MIN(SUM(O15,Y14)-SUM(T15:T15),SUM(E15,J15)),0) -> 0 | W15: {=IF(Первоначальный[[#This Row],[Итого остаток на начало периода]]<1,0, _xlfn.IFS( AND(TYPE(VLOOKUP(1,$Z$12:Z15,1,0))=16,Первоначальный[[#This Row],[Досрочное погашение (да/"")]]=""),0, AND(S14=0,Первоначальный[[#This Row],[Дата платежа из графика]]<>1,Первоначальный[[#This Row],[Платеж ОД по графику]]<>0,Первоначальный[[#This Row],[Полученный платеж]]<>0),MIN(Первоначальный[[#This Row],[Полученный платеж]]+Y14-SUM(Первоначальный[[#This Row],[Полученный платёж по процентам]],Первоначальный[[#This Row],[Полученный платёж по процентам на просроченный ОД]],Первоначальный[[#This Row],[Полученный платёж по прочим комиссиям]]),VLOOKUP(LOOKUP(,-1/($Z$12:Z15=1),$A$12:A15),График[[Срок конец]:[Возврат основной суммы долга]],3,0)), AND(S14=0,Первоначальный[[#This Row],[Дата платежа из графика]]="",Первоначальный[[#This Row],[Досрочное погашение (да/"")]]<>"Да"),0, AND(S14=0,Первоначальный[[#This Row],[Досрочное погашение (да/"")]]=""),MIN(Первоначальный[[#This Row],[Полученный платеж]]+Y14-SUM(Первоначальный[[#This Row],[Полученный платёж по процентам]],Первоначальный[[#This Row],[Полученный платёж по процентам на просроченный ОД]],Первоначальный[[#This Row],[Полученный платёж по прочим комиссиям]]),VLOOKUP(LOOKUP(,-1/($Z$12:Z15=1),$A$12:A15),График[[Срок конец]:[Возврат основной суммы долга]],3,0)), Первоначальный[[#This Row],[Досрочное погашение (да/"")]]="Да",MIN(Первоначальный[[#This Row],[Полученный платеж]]+Y14-SUM(Первоначальный[[#This Row],[Полученный платёж по процентам]],Первоначальный[[#This Row],[Полученный платёж по процентам на просроченный ОД]],Первоначальный[[#This Row],[Полученный платёж по прочим комиссиям]]),Первоначальный[[#This Row],[Остаток ОД на начало периода]]), S14>0,MIN(Первоначальный[[#This Row],[Полученный платеж]]+Y14-SUM(Первоначальный[[#This Row],[Полученный платёж по процентам]],Первоначальный[[#This Row],[Полученный платёж по процентам на просроченный ОД]],Первоначальный[[#This Row],[Полученный платёж по прочим комиссиям]]),SUM(INDIRECT("M"&(MAX((1=S$12:S14)*ROW(S$12:S14),ROW($W$12))&":M"&(ROW()))))-SUM(INDIRECT("W"&(MAX((1=S$12:S14)*ROW(S$12:S14),ROW($W$12))&":W"&(ROW()-1))))) ) )} -> 0 | X15: =MAX(MIN(SUM(O15,Y14)-SUM(T15:W15),SUM(F15,K15)),0) -> 0 | Y15: =ROUND(Y14+O15-SUM(T15:X15),2) -> 0 | Z15: =IF(TYPE((VLOOKUP(Первоначальный[[#This Row],[Дата платежа]],График[Срок конец],1,0)))=16,"",1) | AC15: =Первоначальный[[#This Row],[Остаток ОД на начало периода]]-Первоначальный[[#This Row],[Полученный платёж по ОД]]+Первоначальный[[#This Row],[Выдача ОД за период]] -> 150000 | AD15: =Первоначальный[[#This Row],[Остаток процентов на начало периода]]+Первоначальный[[#This Row],[Проценты за период]]-Первоначальный[[#This Row],[Полученный платёж по процентам]] -> 163.12 | AE15: =Первоначальный[[#This Row],[Остаток процентов на просроченный ОД на начало периода]]+Первоначальный[[#This Row],[Проценты на просроченный платеж по ОД за период]]-Первоначальный[[#This Row],[Полученный платёж по процентам на просроченный ОД]] -> 0 | AF15: =Первоначальный[[#This Row],[Остаток прочих комиссий на начало периода]]+Первоначальный[[#This Row],[Комиссия за период]]-Первоначальный[[#This Row],[Полученный платёж по прочим комиссиям]] -> 0 | AG15: =Первоначальный[[#This Row],[Неустойка на начало периода]]+Первоначальный[[#This Row],[Неустойка за период]]-Первоначальный[[#This Row],[Полученный платёж по неустойке]] -> 0 | AK15: =SUM(AC15:AJ15) -> 150163.12 | AL15: {=MAX((УслРестрактов[Характеристика]="Дата реструктуризации")*(УслРестрактов[Значение]=Первоначальный!$A15),0)} -> 0
A16: =A15+1 -> 44147 | B16: =AC15 -> 150000 | C16: =AD15+AI15 -> 163.12 | D16: =AE15+AJ15 -> 0 | E16: =AF15 -> 0 | F16: =AG15+AH15 -> 0 | G16: =AK15 -> 150163.12 | H16: =ROUND($B16*VLOOKUP($A16,$A$1:$B$10,2,1)/(365+IF(MOD(YEAR($A16),4),0,1)*($A16-$A15)),2)-Первоначальный[[#This Row],[Проценты на просроченный платеж по ОД за период]] -> 81.56 | I16: =ROUND(P15*VLOOKUP($A16,$A$1:$B$10,2,1)/(365+IF(MOD(YEAR($A16),4),0,1)*($A16-$A15)),2) -> 0 | J16: 0 | K16: =IF(S16<>0,R16*$B$7,0) -> 0 | L16: 0 | M16: =SUMIFS(График[Возврат основной суммы долга],График[Дата с учетом нерабочих дней],$A16) -> 0 | N16: =SUMIFS(График[Возврат начисленных %],График[Дата с учетом нерабочих дней],$A16) -> 0 | O16: 0 | P16: {=MAX(IF(AA15="Да",0,SUM(INDIRECT("M"&(MAX(("Да"=AA$12:AA15)*ROW(AA$12:AA15)+1,ROW($P$12))&":M"&(ROW()))))-SUM(INDIRECT("W"&(MAX(("Да"=AA$12:AA15)*ROW(AA$12:AA15)+1,ROW($P$12))&":W"&(ROW()))))),0)} -> 0 | Q16: =MAX(SUM($N$13:N16)-SUM($T$13:T16),0) -> 0 | R16: =Первоначальный[[#This Row],[Просроченный платеж по ОД]]+Первоначальный[[#This Row],[Просроченный платеж по процентам]] -> 0 | S16: =IF(Первоначальный[[#This Row],[Просроченный платеж]]<1,0,S15+1) -> 0 | T16: {=IF(Первоначальный[[#This Row],[Итого остаток на начало периода]]<1,0, IF( AND(TYPE(VLOOKUP(1,$Z$12:Z16,1,0))=16,Первоначальный[[#This Row],[Досрочное погашение (да/"")]]=""),0, _xlfn.IFS(AND(S15=0,Первоначальный[[#This Row],[Дата платежа из графика]]<>1,Первоначальный[[#This Row],[Платеж процентов и комиссий по графику]]<>0,Первоначальный[[#This Row],[Полученный платеж]]<>0),MIN(LOOKUP(,-1/($Z$12:Z16=1),$C$12:C16)+LOOKUP(,-1/($Z$12:Z16=1),$H$12:H16),Первоначальный[[#This Row],[Полученный платеж]]+Y15), AND(Первоначальный[[#This Row],[Досрочное погашение (да/"")]]="Да",Первоначальный[[#This Row],[Цель досрочного погашения (ОД/"")]]<>"ОД"),MIN(Первоначальный[[#This Row],[Полученный платеж]]+Y15,SUM(Первоначальный[[#This Row],[Остаток процентов на начало периода]],Первоначальный[[#This Row],[Проценты за период]])), AND(S15=0,Первоначальный[[#This Row],[Дата платежа из графика]]=""),0, AND(S15=0,Первоначальный[[#This Row],[Дата платежа из графика]]=1,MAX((0<>S$12:S15)*ROW(S$12:S15),ROW($S$12))>=MAX((1=Z$12:Z15)*ROW(Z$12:Z15),ROW($T$12)),TYPE(VLOOKUP("Да",(INDIRECT("AA"&(MAX((1=Z$12:Z15)*ROW(Z$12:Z15),ROW($T$12))&":AA"&(ROW()-1)))),1,0))=16),MIN(LOOKUP(,-1/($Z$12:Z16=1),$C$12:C16)+LOOKUP(,-1/($Z$12:Z16=1),$H$12:H16),Первоначальный[[#This Row],[Полученный платеж]]+Y15), AND(S15=0,TYPE(VLOOKUP("Да",(INDIRECT("AA"&(MAX((1=Z$12:Z15)*ROW(Z$12:Z15),ROW($T$12))&":AA"&(ROW()-1)))),1,0))<>16),MIN(LOOKUP(,-1/($Z$12:Z16=1),$C$12:C16)+LOOKUP(,-1/($Z$12:Z16=1),$H$12:H16)-IF(AA15="Да",0,SUM(INDIRECT("T"&(MAX(("Да"=AA$12:AA15)*ROW(AA$12:AA15)+1,ROW($T$12))&":T"&(ROW()-1))))),Первоначальный[[#This Row],[Полученный платеж]]+Y15), AND(S15=0,MAX((0<>N$12:N15)*ROW(N$12:N15),ROW($S$12))>=MAX((1=Z$12:Z15)*ROW(Z$12:Z15),ROW($T$12))),MIN(LOOKUP(,-1/($Z$12:Z16=1),$C$12:C16)+LOOKUP(,-1/($Z$12:Z16=1),$H$12:H16)-IF(N15<>0,0,SUM(INDIRECT("T"&(MAX((0<>N$12:N15)*ROW(N$12:N15)+1,ROW($T$12))&":T"&(ROW()-1))))),Первоначальный[[#This Row],[Полученный платеж]]+Y15), AND(S15=0,Первоначальный[[#This Row],[Дата платежа из графика]]=1),MIN(LOOKUP(,-1/($Z$12:Z16=1),$C$12:C16)+LOOKUP(,-1/($Z$12:Z16=1),$H$12:H16)-IF(Z15=1,0,SUM(INDIRECT("T"&(MAX((1=Z$12:Z15)*ROW(Z$12:Z15)+1,ROW($T$12))&":T"&(ROW()-1))))),Первоначальный[[#This Row],[Полученный платеж]]+Y15), AND(Z15>0,Первоначальный[[#This Row],[Дата платежа из графика]]=1),MIN(Первоначальный[[#This Row],[Остаток процентов на начало периода]]+Первоначальный[[#This Row],[Проценты за период]],Первоначальный[[#This Row],[Полученный платеж]]+Y15), AND(S15>0,MAX((0<>S$12:S15)*ROW(S$12:S15),ROW($S$12))>=MAX((1=Z$12:Z15)*ROW(Z$12:Z15),ROW($T$12)),TYPE(VLOOKUP("Да",(INDIRECT("AA"&(MAX((1=Z$12:Z15)*ROW(Z$12:Z15),ROW($T$12))&":AA"&(ROW()-1)))),1,0))=16),MIN(LOOKUP(,-1/($Z$12:Z16=1),$C$12:C16)+LOOKUP(,-1/($Z$12:Z16=1),$H$12:H16)-SUM(INDIRECT("T"&(MAX((1=Z$12:Z15)*ROW(Z$12:Z15),ROW($T$12))&":T"&(ROW()-1)))),Первоначальный[[#This Row],[Полученный платеж]]+Y15), S15>0,MIN(LOOKUP(,-1/($Z$12:Z16=1),$C$12:C16)+LOOKUP(,-1/($Z$12:Z16=1),$H$12:H16)-IF(Z15=1,0,SUM(INDIRECT("T"&(MAX((1=Z$12:Z15)*ROW(Z$12:Z15)+1,ROW($T$12))&":T"&(ROW()-1))))),Первоначальный[[#This Row],[Полученный платеж]]+Y15) ) ) )} -> 0 | U16: =MIN(Первоначальный[[#This Row],[Остаток процентов на просроченный ОД на начало периода]]+Первоначальный[[#This Row],[Проценты на просроченный платеж по ОД за период]],Первоначальный[[#This Row],[Полученный платеж]]+Y15-Первоначальный[[#This Row],[Полученный платёж по процентам]]) -> 0 | V16: =MAX(MIN(SUM(O16,Y15)-SUM(T16:T16),SUM(E16,J16)),0) -> 0 | W16: {=IF(Первоначальный[[#This Row],[Итого остаток на начало периода]]<1,0, _xlfn.IFS( AND(TYPE(VLOOKUP(1,$Z$12:Z16,1,0))=16,Первоначальный[[#This Row],[Досрочное погашение (да/"")]]=""),0, AND(S15=0,Первоначальный[[#This Row],[Дата платежа из графика]]<>1,Первоначальный[[#This Row],[Платеж ОД по графику]]<>0,Первоначальный[[#This Row],[Полученный платеж]]<>0),MIN(Первоначальный[[#This Row],[Полученный платеж]]+Y15-SUM(Первоначальный[[#This Row],[Полученный платёж по процентам]],Первоначальный[[#This Row],[Полученный платёж по процентам на просроченный ОД]],Первоначальный[[#This Row],[Полученный платёж по прочим комиссиям]]),VLOOKUP(LOOKUP(,-1/($Z$12:Z16=1),$A$12:A16),График[[Срок конец]:[Возврат основной суммы долга]],3,0)), AND(S15=0,Первоначальный[[#This Row],[Дата платежа из графика]]="",Первоначальный[[#This Row],[Досрочное погашение (да/"")]]<>"Да"),0, AND(S15=0,Первоначальный[[#This Row],[Досрочное погашение (да/"")]]=""),MIN(Первоначальный[[#This Row],[Полученный платеж]]+Y15-SUM(Первоначальный[[#This Row],[Полученный платёж по процентам]],Первоначальный[[#This Row],[Полученный платёж по процентам на просроченный ОД]],Первоначальный[[#This Row],[Полученный платёж по прочим комиссиям]]),VLOOKUP(LOOKUP(,-1/($Z$12:Z16=1),$A$12:A16),График[[Срок конец]:[Возврат основной суммы долга]],3,0)), Первоначальный[[#This Row],[Досрочное погашение (да/"")]]="Да",MIN(Первоначальный[[#This Row],[Полученный платеж]]+Y15-SUM(Первоначальный[[#This Row],[Полученный платёж по процентам]],Первоначальный[[#This Row],[Полученный платёж по процентам на просроченный ОД]],Первоначальный[[#This Row],[Полученный платёж по прочим комиссиям]]),Первоначальный[[#This Row],[Остаток ОД на начало периода]]), S15>0,MIN(Первоначальный[[#This Row],[Полученный платеж]]+Y15-SUM(Первоначальный[[#This Row],[Полученный платёж по процентам]],Первоначальный[[#This Row],[Полученный платёж по процентам на просроченный ОД]],Первоначальный[[#This Row],[Полученный платёж по прочим комиссиям]]),SUM(INDIRECT("M"&(MAX((1=S$12:S15)*ROW(S$12:S15),ROW($W$12))&":M"&(ROW()))))-SUM(INDIRECT("W"&(MAX((1=S$12:S15)*ROW(S$12:S15),ROW($W$12))&":W"&(ROW()-1))))) ) )} -> 0 | X16: =MAX(MIN(SUM(O16,Y15)-SUM(T16:W16),SUM(F16,K16)),0) -> 0 | Y16: =ROUND(Y15+O16-SUM(T16:X16),2) -> 0 | Z16: =IF(TYPE((VLOOKUP(Первоначальный[[#This Row],[Дата платежа]],График[Срок конец],1,0)))=16,"",1) | AC16: =Первоначальный[[#This Row],[Остаток ОД на начало периода]]-Первоначальный[[#This Row],[Полученный платёж по ОД]]+Первоначальный[[#This Row],[Выдача ОД за период]] -> 150000 | AD16: =Первоначальный[[#This Row],[Остаток процентов на начало периода]]+Первоначальный[[#This Row],[Проценты за период]]-Первоначальный[[#This Row],[Полученный платёж по процентам]] -> 244.68 | AE16: =Первоначальный[[#This Row],[Остаток процентов на просроченный ОД на начало периода]]+Первоначальный[[#This Row],[Проценты на просроченный платеж по ОД за период]]-Первоначальный[[#This Row],[Полученный платёж по процентам на просроченный ОД]] -> 0 | AF16: =Первоначальный[[#This Row],[Остаток прочих комиссий на начало периода]]+Первоначальный[[#This Row],[Комиссия за период]]-Первоначальный[[#This Row],[Полученный платёж по прочим комиссиям]] -> 0 | AG16: =Первоначальный[[#This Row],[Неустойка на начало периода]]+Первоначальный[[#This Row],[Неустойка за период]]-Первоначальный[[#This Row],[Полученный платёж по неустойке]] -> 0 | AK16: =SUM(AC16:AJ16) -> 150244.68 | AL16: {=MAX((УслРестрактов[Характеристика]="Дата реструктуризации")*(УслРестрактов[Значение]=Первоначальный!$A16),0)} -> 0
A17: =A16+1 -> 44148 | B17: =AC16 -> 150000 | C17: =AD16+AI16 -> 244.68 | D17: =AE16+AJ16 -> 0 | E17: =AF16 -> 0 | F17: =AG16+AH16 -> 0 | G17: =AK16 -> 150244.68 | H17: =ROUND($B17*VLOOKUP($A17,$A$1:$B$10,2,1)/(365+IF(MOD(YEAR($A17),4),0,1)*($A17-$A16)),2)-Первоначальный[[#This Row],[Проценты на просроченный платеж по ОД за период]] -> 81.56 | I17: =ROUND(P16*VLOOKUP($A17,$A$1:$B$10,2,1)/(365+IF(MOD(YEAR($A17),4),0,1)*($A17-$A16)),2) -> 0 | J17: 0 | K17: =IF(S17<>0,R17*$B$7,0) -> 0 | L17: 0 | M17: =SUMIFS(График[Возврат основной суммы долга],График[Дата с учетом нерабочих дней],$A17) -> 0 | N17: =SUMIFS(График[Возврат начисленных %],График[Дата с учетом нерабочих дней],$A17) -> 0 | O17: 0 | P17: {=MAX(IF(AA16="Да",0,SUM(INDIRECT("M"&(MAX(("Да"=AA$12:AA16)*ROW(AA$12:AA16)+1,ROW($P$12))&":M"&(ROW()))))-SUM(INDIRECT("W"&(MAX(("Да"=AA$12:AA16)*ROW(AA$12:AA16)+1,ROW($P$12))&":W"&(ROW()))))),0)} -> 0 | Q17: =MAX(SUM($N$13:N17)-SUM($T$13:T17),0) -> 0 | R17: =Первоначальный[[#This Row],[Просроченный платеж по ОД]]+Первоначальный[[#This Row],[Просроченный платеж по процентам]] -> 0 | S17: =IF(Первоначальный[[#This Row],[Просроченный платеж]]<1,0,S16+1) -> 0 | T17: {=IF(Первоначальный[[#This Row],[Итого остаток на начало периода]]<1,0, IF( AND(TYPE(VLOOKUP(1,$Z$12:Z17,1,0))=16,Первоначальный[[#This Row],[Досрочное погашение (да/"")]]=""),0, _xlfn.IFS(AND(S16=0,Первоначальный[[#This Row],[Дата платежа из графика]]<>1,Первоначальный[[#This Row],[Платеж процентов и комиссий по графику]]<>0,Первоначальный[[#This Row],[Полученный платеж]]<>0),MIN(LOOKUP(,-1/($Z$12:Z17=1),$C$12:C17)+LOOKUP(,-1/($Z$12:Z17=1),$H$12:H17),Первоначальный[[#This Row],[Полученный платеж]]+Y16), AND(Первоначальный[[#This Row],[Досрочное погашение (да/"")]]="Да",Первоначальный[[#This Row],[Цель досрочного погашения (ОД/"")]]<>"ОД"),MIN(Первоначальный[[#This Row],[Полученный платеж]]+Y16,SUM(Первоначальный[[#This Row],[Остаток процентов на начало периода]],Первоначальный[[#This Row],[Проценты за период]])), AND(S16=0,Первоначальный[[#This Row],[Дата платежа из графика]]=""),0, AND(S16=0,Первоначальный[[#This Row],[Дата платежа из графика]]=1,MAX((0<>S$12:S16)*ROW(S$12:S16),ROW($S$12))>=MAX((1=Z$12:Z16)*ROW(Z$12:Z16),ROW($T$12)),TYPE(VLOOKUP("Да",(INDIRECT("AA"&(MAX((1=Z$12:Z16)*ROW(Z$12:Z16),ROW($T$12))&":AA"&(ROW()-1)))),1,0))=16),MIN(LOOKUP(,-1/($Z$12:Z17=1),$C$12:C17)+LOOKUP(,-1/($Z$12:Z17=1),$H$12:H17),Первоначальный[[#This Row],[Полученный платеж]]+Y16), AND(S16=0,TYPE(VLOOKUP("Да",(INDIRECT("AA"&(MAX((1=Z$12:Z16)*ROW(Z$12:Z16),ROW($T$12))&":AA"&(ROW()-1)))),1,0))<>16),MIN(LOOKUP(,-1/($Z$12:Z17=1),$C$12:C17)+LOOKUP(,-1/($Z$12:Z17=1),$H$12:H17)-IF(AA16="Да",0,SUM(INDIRECT("T"&(MAX(("Да"=AA$12:AA16)*ROW(AA$12:AA16)+1,ROW($T$12))&":T"&(ROW()-1))))),Первоначальный[[#This Row],[Полученный платеж]]+Y16), AND(S16=0,MAX((0<>N$12:N16)*ROW(N$12:N16),ROW($S$12))>=MAX((1=Z$12:Z16)*ROW(Z$12:Z16),ROW($T$12))),MIN(LOOKUP(,-1/($Z$12:Z17=1),$C$12:C17)+LOOKUP(,-1/($Z$12:Z17=1),$H$12:H17)-IF(N16<>0,0,SUM(INDIRECT("T"&(MAX((0<>N$12:N16)*ROW(N$12:N16)+1,ROW($T$12))&":T"&(ROW()-1))))),Первоначальный[[#This Row],[Полученный платеж]]+Y16), AND(S16=0,Первоначальный[[#This Row],[Дата платежа из графика]]=1),MIN(LOOKUP(,-1/($Z$12:Z17=1),$C$12:C17)+LOOKUP(,-1/($Z$12:Z17=1),$H$12:H17)-IF(Z16=1,0,SUM(INDIRECT("T"&(MAX((1=Z$12:Z16)*ROW(Z$12:Z16)+1,ROW($T$12))&":T"&(ROW()-1))))),Первоначальный[[#This Row],[Полученный платеж]]+Y16), AND(Z16>0,Первоначальный[[#This Row],[Дата платежа из графика]]=1),MIN(Первоначальный[[#This Row],[Остаток процентов на начало периода]]+Первоначальный[[#This Row],[Проценты за период]],Первоначальный[[#This Row],[Полученный платеж]]+Y16), AND(S16>0,MAX((0<>S$12:S16)*ROW(S$12:S16),ROW($S$12))>=MAX((1=Z$12:Z16)*ROW(Z$12:Z16),ROW($T$12)),TYPE(VLOOKUP("Да",(INDIRECT("AA"&(MAX((1=Z$12:Z16)*ROW(Z$12:Z16),ROW($T$12))&":AA"&(ROW()-1)))),1,0))=16),MIN(LOOKUP(,-1/($Z$12:Z17=1),$C$12:C17)+LOOKUP(,-1/($Z$12:Z17=1),$H$12:H17)-SUM(INDIRECT("T"&(MAX((1=Z$12:Z16)*ROW(Z$12:Z16),ROW($T$12))&":T"&(ROW()-1)))),Первоначальный[[#This Row],[Полученный платеж]]+Y16), S16>0,MIN(LOOKUP(,-1/($Z$12:Z17=1),$C$12:C17)+LOOKUP(,-1/($Z$12:Z17=1),$H$12:H17)-IF(Z16=1,0,SUM(INDIRECT("T"&(MAX((1=Z$12:Z16)*ROW(Z$12:Z16)+1,ROW($T$12))&":T"&(ROW()-1))))),Первоначальный[[#This Row],[Полученный платеж]]+Y16) ) ) )} -> 0 | U17: =MIN(Первоначальный[[#This Row],[Остаток процентов на просроченный ОД на начало периода]]+Первоначальный[[#This Row],[Проценты на просроченный платеж по ОД за период]],Первоначальный[[#This Row],[Полученный платеж]]+Y16-Первоначальный[[#This Row],[Полученный платёж по процентам]]) -> 0 | V17: =MAX(MIN(SUM(O17,Y16)-SUM(T17:T17),SUM(E17,J17)),0) -> 0 | W17: {=IF(Первоначальный[[#This Row],[Итого остаток на начало периода]]<1,0, _xlfn.IFS( AND(TYPE(VLOOKUP(1,$Z$12:Z17,1,0))=16,Первоначальный[[#This Row],[Досрочное погашение (да/"")]]=""),0, AND(S16=0,Первоначальный[[#This Row],[Дата платежа из графика]]<>1,Первоначальный[[#This Row],[Платеж ОД по графику]]<>0,Первоначальный[[#This Row],[Полученный платеж]]<>0),MIN(Первоначальный[[#This Row],[Полученный платеж]]+Y16-SUM(Первоначальный[[#This Row],[Полученный платёж по процентам]],Первоначальный[[#This Row],[Полученный платёж по процентам на просроченный ОД]],Первоначальный[[#This Row],[Полученный платёж по прочим комиссиям]]),VLOOKUP(LOOKUP(,-1/($Z$12:Z17=1),$A$12:A17),График[[Срок конец]:[Возврат основной суммы долга]],3,0)), AND(S16=0,Первоначальный[[#This Row],[Дата платежа из графика]]="",Первоначальный[[#This Row],[Досрочное погашение (да/"")]]<>"Да"),0, AND(S16=0,Первоначальный[[#This Row],[Досрочное погашение (да/"")]]=""),MIN(Первоначальный[[#This Row],[Полученный платеж]]+Y16-SUM(Первоначальный[[#This Row],[Полученный платёж по процентам]],Первоначальный[[#This Row],[Полученный платёж по процентам на просроченный ОД]],Первоначальный[[#This Row],[Полученный платёж по прочим комиссиям]]),VLOOKUP(LOOKUP(,-1/($Z$12:Z17=1),$A$12:A17),График[[Срок конец]:[Возврат основной суммы долга]],3,0)), Первоначальный[[#This Row],[Досрочное погашение (да/"")]]="Да",MIN(Первоначальный[[#This Row],[Полученный платеж]]+Y16-SUM(Первоначальный[[#This Row],[Полученный платёж по процентам]],Первоначальный[[#This Row],[Полученный платёж по процентам на просроченный ОД]],Первоначальный[[#This Row],[Полученный платёж по прочим комиссиям]]),Первоначальный[[#This Row],[Остаток ОД на начало периода]]), S16>0,MIN(Первоначальный[[#This Row],[Полученный платеж]]+Y16-SUM(Первоначальный[[#This Row],[Полученный платёж по процентам]],Первоначальный[[#This Row],[Полученный платёж по процентам на просроченный ОД]],Первоначальный[[#This Row],[Полученный платёж по прочим комиссиям]]),SUM(INDIRECT("M"&(MAX((1=S$12:S16)*ROW(S$12:S16),ROW($W$12))&":M"&(ROW()))))-SUM(INDIRECT("W"&(MAX((1=S$12:S16)*ROW(S$12:S16),ROW($W$12))&":W"&(ROW()-1))))) ) )} -> 0 | X17: =MAX(MIN(SUM(O17,Y16)-SUM(T17:W17),SUM(F17,K17)),0) -> 0 | Y17: =ROUND(Y16+O17-SUM(T17:X17),2) -> 0 | Z17: =IF(TYPE((VLOOKUP(Первоначальный[[#This Row],[Дата платежа]],График[Срок конец],1,0)))=16,"",1) | AC17: =Первоначальный[[#This Row],[Остаток ОД на начало периода]]-Первоначальный[[#This Row],[Полученный платёж по ОД]]+Первоначальный[[#This Row],[Выдача ОД за период]] -> 150000 | AD17: =Первоначальный[[#This Row],[Остаток процентов на начало периода]]+Первоначальный[[#This Row],[Проценты за период]]-Первоначальный[[#This Row],[Полученный платёж по процентам]] -> 326.24 | AE17: =Первоначальный[[#This Row],[Остаток процентов на просроченный ОД на начало периода]]+Первоначальный[[#This Row],[Проценты на просроченный платеж по ОД за период]]-Первоначальный[[#This Row],[Полученный платёж по процентам на просроченный ОД]] -> 0 | AF17: =Первоначальный[[#This Row],[Остаток прочих комиссий на начало периода]]+Первоначальный[[#This Row],[Комиссия за период]]-Первоначальный[[#This Row],[Полученный платёж по прочим комиссиям]] -> 0 | AG17: =Первоначальный[[#This Row],[Неустойка на начало периода]]+Первоначальный[[#This Row],[Неустойка за период]]-Первоначальный[[#This Row],[Полученный платёж по неустойке]] -> 0 | AK17: =SUM(AC17:AJ17) -> 150326.24 | AL17: {=MAX((УслРестрактов[Характеристика]="Дата реструктуризации")*(УслРестрактов[Значение]=Первоначальный!$A17),0)} -> 0
